Workbook

Sheet DATABASE
A1: SID | B1: ALAMAT2 | C1: KATEGORI LOKASI | D1: IP | E1: TANGGAL AKTIVASI | F1: MIKROTIK/NON MIKROTIK | G1: KET | H1: KET
A2: 2048973283 | B2: Bank Jatim u/ Host To Host Metro Universitas Sebelas Maret Surakarta (UNS) menuju Data Center Bank Jatim, JL IR SUTAMI JEBRES KEC JEBRES SURAKARTA, SURAKARTA,00 | C2: H2H METRO | D2: - | E2: 45361
A3: 2048972881 | B3: Bank Jatim u/ Host To Host Metro Universitas Sebelas Maret Surakarta (UNS) menuju Data Center Bank Jatim, KAPTEN SUBIJANTO, TANGERANG,RAK NO 6,LT 3,GED GRAHA TLKM SIGMA | C3: H2H METRO | D3: - | E3: 45361
A4: 1711167464 | B4: Bank Jatim u/ Host To Host Metro Teluk Lamong Jl. Osowilangun KM 12, Surabaya | C4: H2H METRO | D4: - | E4: 20/06/2022
A5: 1711162474 | B5: Bank Jatim u/ Host To Host Metro Teluk Lamong, Data Center Bank Jatim, Gedung Graha Telkom Sigma Lt. 3 Wing Timur, BSD Tangerang | C5: H2H METRO | D5: - | E5: 20/06/2022
A6: 1261472344 | B6: Bank Jatim u/ Host To Host Metro Bpjs T.Kerja JL. Medan Merdeka Barat 13-14, Jakarta Pusat | C6: H2H METRO | D6: - | E6: 26/03/2021
A7: 1261472394 | B7: Bank Jatim u/ Host To Host Metro BPJS Graha Sigma Lt.6, Tangerang | C7: H2H METRO | D7: - | E7: 26/03/2021
A8: 790038103 | B8: Bank Jatim u/ Host To Host Metro P2P DC-MKM; Data Center Jl. Gedung German Center Lt. 3, BSD Tangerang ke DCI Bekasi (H2H MKM DCI Tangerang) | C8: H2H METRO | D8: - | E8: 43497
A9: 790226991 | B9: Bank Jatim u/ Host To Host Metro P2P MKM-DC; DCI Bekasi, Jl. Halmahera Blok F1 No.1, Danau Indah, Cikarang Bar, Bekasi ke (H2H MKM DCI Tangerang) | C9: H2H METRO | D9: - | E9: 43497
A10: 4700020-0031135108 | B10: Bank Jatim u/ Host To Host Metro DC- Asabri; Sigma Citraland Jl.Bukit Bali B3 2 Lakarsantri Surabaya | C10: H2H METRO | D10: - | E10: 31/10/2017
A11: 4700020-0031134693 | B11: Bank Jatim u/ Host To Host Metro Asabri -DC; Jl.Mayjen Sutoyo 11 JakTim | C11: H2H METRO | D11: - | E11: 26/10/2017
A12: 4700020-0030871897 | B12: Bank Jatim u/ Host To Host Metro DC -DJP; DC Sigma Citraland SBY ke Jl. Gatot Subroto Kav. 40-42 JKT (E-Filling) | C12: H2H METRO | D12: - | E12: 18/04/2017
A13: 4700020-0029669221 | B13: Bank Jatim u/ Host To Host Metro DJP-DC; Jl. Gatot Subroto Kav. 40-42 JKT ke DC Sigma Citraland SBY (E-Filling) | C13: H2H METRO | D13: - | E13: 26/01/2016
A14: 2095151855/2095149600 | B14: Bank Jatim Neucentrix Gubeng, Jl.Sumatera No.131 Lt 3 Kec Gubeng , Surabaya | C14: COLOCATION | D14: 36.64.131.241/29 | E14: 46003 | G14: 4700020-0003122034/2095151855/2095149600
A15: 4700020-0031816657 | B15: ATM UNMUH Jl.Ry Tlogomas 246 Malang (PRORATA CABUT) | C15: ATM | D15: 196.168.117.201/29 | E15: 43717
A16: 941041295 | B16: Payment Point Sistem Administrasi Manunggal Satu Atap Pasuruan Jl.SultanAgung 80,Purutrejo,Purworejo (PRORATA CABUT) | C16: PAYMENT POINT | D16: 196.168.117.201/29 | E16: 44963
A17: 1707535922 | B17: Bank Jatim u/ Aplikasi JKD BANK INDONESIA JL. Kapten Subijanto LT. 5, German Center BSD Tangerang Selatan | C17: JKD BI | D17: - | E17: 43717
A18: /1792983850 | B18: Kantor Fungsional RSUD Nganjuk, Jl.Sutomo 62 | C18: KANTOR FUNGSIONAL | D18: 196.168.100.49/28 | E18: 43717 | G18: 4700020-42970/1792983850
A19: 4700020-0020560544 | B19: PBB Dispenda Sampang Jl Rajawali, Sampang | C19: PBB | D19: 192.168.151.130/30 | E19: 42278
A20: 1165671440 | B20: Kantor Kas KPP Utara Gresik, Jl. Wahidin Sudirohusodo 700 Gresik | C20: KANTOR KAS | D20: 196.168.100.113/28 | E20: 28/01/2020 | G20: DO JULI 2025
A21: 4700020-0004568476 | B21: ATM RS. Pura Raharja, Jl. Pucang Adi 12-14, Surabaya | C21: ATM | D21: 196.168.201.1/29 | E21: -
A22: 835049177 | B22: Host To Host Dinas Kependidikan Surabaya JL Jagir Wonokromo 356, Sidosermo | C22: H2H | D22: 192.168.150.70/30 | E22: -
A23: 2018687049 | B23: PP Pasar Kolpajung, JL Ronggo Sukowati, Kolpajung Kec Pamekasan, Kab Pamekasan, Pamekasan | C23: PAYMENT POINT | D23: 172.26.0.193/29 | E23: -
A24: 4700020-0031310385 | B24: Host To Host SP2D JL.Sunan Kalijogo 02 Trenggalek | C24: H2H | D24: 192.168.150.30/30 | E24: -
A25: 4700020-0029555999 | B25: Cabang Batam , Jl. A. Yani Komplek Ruko Centre Park Blok A No 1 Kel. Taman Baloi Kec. Batam Kota Batam | C25: CABANG | D25: 192.168.157.202/30 | E25: - | G25: SID BARU 2076423329
A26: 4700020-38090 | B26: Bank Jatim Internet Kantor Pusat; Jl.Basuki Rahmat No. 98-104, Surabaya ( Astinet ) | C26: INTERNET KANTOR PUSAT | D26: 10.10.30.1 /30 (222.124.169.177 /29) | E26: 26/07/2017
A27: 4700020-92381 | B27: Bank Jatim u/ Host To Host Finnet ; Jl Kapt.Subijanto Graha Telkom Sigma Lt. 3 BSD Lekong - Serpong | C27: H2H | D27: 10.2.254.73 /30 | E27: 42014
A28: 4700020-0029217410 | B28: Bank Jatim u/ Host To Host Artajasa Sigma; Jl. Bukit Bali B3 Lakarsantri Surabaya Lt.3 | C28: SPP ONLINE | D28: 10.240.0.2 /30 | E28: 42677
A29: 4700020-0029298844 | B29: Bank Jatim u/ Host To Host KTP-el Ditjen Dukcapil; DC Sigma Tangerang Lt.3 Wing timur, BSD Tangerang | C29: H2H | D29: 10.240.0.6 /30 | E29: 13/04/2016
A30: 4700020-07470 | B30: Samsat Online Papar, Jl Raya Papar, Kediri | C30: SAMSAT ONLINE | D30: 172.16.152.1 /24 | E30: 42010
A31: 4700020-0004789517 | B31: Payment Point Alun-alun Kt u/ DIPENDA Jl. Merdeka Barat | C31: PAYMENT POINT | D31: 172.16.161.33 /29 | E31: 42342
A32: 2027864991 | B32: ATM Jenu Tuban,Jl.Raya Jenu,Ds.Beji,Kec.Jenu,Tuban | C32: ATM | D32: 172.16.2.57 /30 | E32: 21/01/2024
A33: 1-IPP6AAY/1703056946 | B33: Bank Jatim u/ Bandwith Pelaporan Aplikasi BI-RTGS/SSSS/ETP, Bank Indonesia - RTGS; Telkom Sigma Lakarsantri IVC Surabaya | C33: Aplikasi BI-RTGS/SSSS/ETP BI | D33: 172.16.205.109/30 | E33: 13/01/2022 | G33: Kesepakatan REKON APR 2026 AM Safir dan Pak Rai SID ini BW TETAP di tulis 2Mbps diinvois HARGA PKS Baru , WALO PE 4Mbps
A34: 4700020-0031230943 | B34: Bank Jatim u/ Internet DRC Bank Jatim; JL.Citraland Surabaya ( Astinet ) | C34: INTERNET KANTOR PUSAT | D34: 172.17.171.38 /30 (36.89.37.209 /28) | E34: 29/12/2017
A35: 4700020-82572 | B35: Bank Jatim Backhaul VPN IP DC; Graha Telkom Sigma Lt 3 BSD Tangerang | C35: DC | D35: 172.17.20.2 /30 | E35: 42011
A36: 4700020-65917 | B36: Cabang Lamongan, Pangsud No.74 | C36: CABANG | D36: 172.17.45.169 /30 | E36: 24/12/2024
A37: 2076561882 | B37: Samsat Online Capem Babat, Raya Babat 211 Lamongan | C37: SAMSAT ONLINE | D37: 172.17.45.169 /30 | E37: 24/12/2024
A38: 4700020-68390 | B38: Bank Jatim Backhaul VPN IP DRC; Bukit Bali B3-2 Lakarsantri Surabaya | C38: DRC | D38: 172.17.52.2 /30 | E38: 24/06/2015
A39: 4700020-0021607811 | B39: Samsat Online Capem Cerme, Jl. Tegal Suruh No.3 Cerme Gresik | C39: SAMSAT ONLINE | D39: 172.20.21.1 /26 | E39: 42009
A40: 4700020-06005 | B40: Samsat Online Capem Sidayu, Jl. Pemuda 10, Sidayu | C40: SAMSAT ONLINE | D40: 172.20.21.33 /26 | E40: 42010
...

Sheet JAN26
B2: • TELKOM - MONTHLY RECURRING CHARGES
A3: NO. | B3: JENIS KANTOR | C3: ALAMAT | D3: KATEGORI LOKASI | E3: LAYANAN | F3: TYPE ORDER | G3: ID | H3: PERIOD | I3: Bandwidth | L3: IP Host Telkom | M3: TANGGAL AKTIVASI | N3: TANGGAL MULAI AKTIF LAYANAN (UPGRADE/DOWNGRADE) | O3: PEMAKAIAN AVERAGE (Kbps) | Q3: TRAFFIK TOTAL (Kbps) | S3: DURASI DOWNTIME | T3: SLA | V3: AVAILABILITY (Jam/bulan) | W3: RESTITUSI (Rp) | Y3: HARGA (Rp) | AE3: TOTAL | AF3: HARGA SETELAH RESTITUSI | AG3: SUB TOTAL PER CABANG | AH3: MIKROTIK/NONMIKROTIK | AI3: KETERANGAN
G4: SID JAN 2025 | I4: Eksisting BW | J4: Upgrade BW | K4: Downgrade BW | O4: Eksisting | P4: Upgrade | Q4: Eksisting | R4: Upgrade | S4: (Detik) | T4: SLA ACTUAL | U4: SLA PKS | W4: Restitusi Over SLA | X4: Restitusi Tagihan | Y4: Eksisting | Z4: Upgrade (Prorate) | AA4: Downgrade (Prorate) | AB4: Cabut (Prorate) | AC4: PSB (Prorate) | AD4: Relokasi | AE4: TOTAL | AF4: HARGA SETELAH RESTITUSI | AG4: SUB TOTAL PER CABANG | AH4: MIKROTIK/NONMIKROTIK | AI4: KETERANGAN
A5: A | B5: B | C5: C | D5: D | E5: E | F5: F | G5: G | H5: H | I5: I | J5: J | K5: K | L5: L | M5: M | N5: N | O5: O | P5: P | Q5: Q | R5: R | S5: S | T5: T | U5: U | V5: V | W5: W | X5: X | Y5: Y | Z5: Z | AA5: AA | AB5: AB | AC5: AC | AD5: AD | AE5: AE | AF5: AE | AG5: AG | AH5: AH | AI5: AI
A6: 1 | B6: KANTOR PUSAT | C6: {=_xlfn.XLOOKUP(G6,DATABASE!$A$2:$A$806,DATABASE!$B$2:$B$806)} -> Bank Jatim Internet Kantor Pusat; Jl.Basuki Rahmat No. 98-104, Surabaya ( Astinet ) | D6: {=_xlfn.XLOOKUP(G6,DATABASE!$A$2:$A$808,DATABASE!$C$2:$C$808)} -> INTERNET KANTOR PUSAT | E6: TELKOM ASTINET | F6: EKSISTING | G6: 4700020-38090 | H6: 202512 | I6: 100 Mbps | L6: 10.10.30.1 /30 (222.124.169.177 /29) | M6: 7/26/2017 | O6: 12390.4 | Q6: =(O6*24*3600*30/8)/100000 -> 40144.896 | R6: =(P6*24*3600*30/8)/100000 -> 0 | S6: 0 | T6: =(V6-S6)/V6 -> 1 | U6: 0.99 | V6: 2678400 | W6: =MAX(0, (((S6 - ((1 - VALUE(U6)) * V6)) / V6) * AE6)) -> 0 | X6: 0.00 | Y6: 20412151 | AE6: =SUM(Y6:AD6) -> 20412151 | AF6: =IFERROR(AE6+W6,0) -> 20412151 | AG6: 107313280
A7: =A6+1 -> 2 | B7: KANTOR PUSAT | C7: {=_xlfn.XLOOKUP(G7,DATABASE!$A$2:$A$808,DATABASE!$B$2:$B$808)} -> Bank Jatim Backhaul VPN IP Kantor Pusat; Jl. Basuki Rahmat No 98-104 Surabaya | D7: {=_xlfn.XLOOKUP(G7,DATABASE!$A$2:$A$808,DATABASE!$C$2:$C$808)} -> WAN KANTOR PUSAT | E7: TELKOM VPN IP | F7: EKSISTING | G7: 4700020-10498 | H7: 202512 | I7: 100 Mbps | L7: 192.168.152.2 /30 | M7: 43199 | O7: 48363.52 | Q7: =(O7*24*3600*30/8)/100000 -> 156697.8 | R7: =(P7*24*3600*30/8)/100000 -> 0 | S7: 0 | T7: =(V7-S7)/V7*100% -> 1 | U7: 0.99 | V7: 2678400 | W7: =MAX(0, (((S7 - ((1 - VALUE(U7)) * V7)) / V7) * AE7)) -> 0 | X7: 0.00 | Y7: 20776000 | AE7: =SUM(Y7:AD7) -> 20776000 | AF7: =IFERROR(AE7+W7,0) -> 20776000
A8: =A7+1 -> 3 | B8: KANTOR PUSAT | C8: {=_xlfn.XLOOKUP(G8,DATABASE!$A$2:$A$806,DATABASE!$B$2:$B$806)} -> Bank Jatim Neucentrix Gubeng, Jl.Sumatera No.131 Lt 3 Kec Gubeng , Surabaya | D8: {=_xlfn.XLOOKUP(G8,DATABASE!$A$2:$A$808,DATABASE!$C$2:$C$808)} -> COLOCATION | E8: TELKOM NEUCENTRIX | F8: PASANG BARU | G8: 2095151855/2095149600 | H8: 202512 | I8: 0 | L8: 36.64.131.241/29 | M8: 46003 | N8: 46003 | O8: 234.11 | Q8: =(O8*24*3600*30/8)/100000 -> 758.5164 | R8: =(P8*24*3600*30/8)/100000 -> 0 | S8: 0 | T8: =(V8-S8)/V8*100% -> 1 | U8: 0.99 | V8: 2678400 | W8: =MAX(0, (((S8 - ((1 - VALUE(U8)) * V8)) / V8) * AE8)) -> 0 | X8: 0.00 | Y8: 1377297 | AC8: 0 | AE8: =SUM(Y8:AD8) -> 1377297 | AF8: =IFERROR(AE8+W8,0) -> 1377297 | AI8: MIGRASI KE LAYANAN BARU dengan PASANG BARU DES 2025
A9: =A8+1 -> 4 | B9: KANTOR PUSAT | C9: {=_xlfn.XLOOKUP(G9,DATABASE!$A$2:$A$809,DATABASE!$B$2:$B$809)} -> Bank Jatim u/ PT ACS, JL. Soekarno Hatta 269,Bandung (SMS Banking Primary) | D9: {=_xlfn.XLOOKUP(G9,DATABASE!$A$2:$A$809,DATABASE!$C$2:$C$809)} -> H2H | E9: TELKOM VPN IP | F9: PEMUTUSAN | G9: 4700020-0004645351 | H9: 202512 | I9: 512 Kbps | L9: 192.168.151.150 /30 | M9: 3/14/2015 | N9: 46009 | O9: 5.95 | Q9: =(O9*24*3600*30/8)/100000 -> 19.278 | R9: =(P9*24*3600*30/8)/100000 -> 0 | S9: 0 | T9: =(V9-S9)/V9*100% -> 1 | U9: 0.99 | V9: 2678400 | W9: =MAX(0, (((S9 - ((1 - VALUE(U9)) * V9)) / V9) * AE9)) -> 0 | X9: 0.00 | Y9: 0 | AB9: 1391891 | AE9: =SUM(Y9:AD9) -> 1391891 | AF9: =IFERROR(AE9+W9,0) -> 1391891 | AI9: PEMUTUSAN 18 DES 2025
A10: =A9+1 -> 5 | B10: KANTOR PUSAT | C10: {=_xlfn.XLOOKUP(G10,DATABASE!$A$2:$A$806,DATABASE!$B$2:$B$806)} -> Bank Jatim u/ Host To Host Finnet ; Jl Kapt.Subijanto Graha Telkom Sigma Lt. 3 BSD Lekong - Serpong | D10: {=_xlfn.XLOOKUP(G10,DATABASE!$A$2:$A$809,DATABASE!$C$2:$C$809)} -> H2H | E10: TELKOM VPN IP | F10: EKSISTING | G10: 4700020-92381 | H10: 202512 | I10: 512 Kbps | L10: 10.2.254.73 /30 | M10: 42278 | O10: 1.72108 | Q10: =(O10*24*3600*30/8)/100000 -> 5.5762992 | R10: =(P10*24*3600*30/8)/100000 -> 0 | S10: 0 | T10: =(V10-S10)/V10*100% -> 1 | U10: 0.99 | V10: 2678400 | W10: =MAX(0, (((S10 - ((1 - VALUE(U10)) * V10)) / V10) * AE10)) -> 0 | X10: 0.00 | Y10: 2319819 | AE10: =SUM(Y10:AD10) -> 2319819 | AF10: =IFERROR(AE10+W10,0) -> 2319819
A11: =A10+1 -> 6 | B11: KANTOR PUSAT | C11: {=_xlfn.XLOOKUP(G11,DATABASE!$A$2:$A$806,DATABASE!$B$2:$B$806)} -> Bank Jatim u/ Host To Host MPN G2 KEMENKEU; Graha Telkom Sigma Lt 3 BSD Tangerang | D11: {=_xlfn.XLOOKUP(G11,DATABASE!$A$2:$A$809,DATABASE!$C$2:$C$809)} -> H2H | E11: TELKOM VPN IP | F11: EKSISTING | G11: 4700020-0020988266 | H11: 202512 | I11: 512 Kbps | L11: 172.31.187.161 /30 | M11: 42099 | O11: 15.3 | Q11: =(O11*24*3600*30/8)/100000 -> 49.572 | R11: =(P11*24*3600*30/8)/100000 -> 0 | S11: 0 | T11: =(V11-S11)/V11*100% -> 1 | U11: 0.99 | V11: 2678400 | W11: =MAX(0, (((S11 - ((1 - VALUE(U11)) * V11)) / V11) * AE11)) -> 0 | X11: 0.00 | Y11: 2319819 | AE11: =SUM(Y11:AD11) -> 2319819 | AF11: =IFERROR(AE11+W11,0) -> 2319819
A12: =A11+1 -> 7 | B12: KANTOR PUSAT | C12: {=_xlfn.XLOOKUP(G12,DATABASE!$A$2:$A$806,DATABASE!$B$2:$B$806)} -> Bank Jatim u/ Bandwith Pelaporan Aplikasi BI-RTGS/SSSS/ETP, Bank Indonesia - RTGS; Telkom Sigma Lakarsantri IVC Surabaya | D12: {=_xlfn.XLOOKUP(G12,DATABASE!$A$2:$A$809,DATABASE!$C$2:$C$809)} -> Aplikasi BI-RTGS/SSSS/ETP BI | E12: TELKOM MANAGED NETWORK | F12: EKSISTING | G12: 1-IPP6AAY/1703056946 | H12: 202512 | I12: 2 Mbps | L12: 172.16.205.109/30 | M12: 1/13/2022 | O12: 86.18 | Q12: =(O12*24*3600*30/8)/100000 -> 279.2232 | R12: =(P12*24*3600*30/8)/100000 -> 0 | S12: 0 | T12: =(V12-S12)/V12*100% -> 1 | U12: 0.99 | V12: 2678400 | W12: =MAX(0, (((S12 - ((1 - VALUE(U12)) * V12)) / V12) * AE12)) -> 0 | X12: 0.00 | Y12: 5782000 | AE12: =SUM(Y12:AD12) -> 5782000 | AF12: =IFERROR(AE12+W12,0) -> 5782000 | AI12: Kesepakatan REKON APR 2026 AM Safir dan Pak Rai SID ini BW TETAP di tulis 2Mbps diinvois HARGA PKS Baru , WALO PE 4Mbps
A13: =A12+1 -> 8 | B13: KANTOR PUSAT | C13: {=_xlfn.XLOOKUP(G13,DATABASE!$A$2:$A$806,DATABASE!$B$2:$B$806)} -> Bank Jatim u/ Host To Host Artajasa Sigma; Jl. Bukit Bali B3 Lakarsantri Surabaya Lt.3 | D13: {=_xlfn.XLOOKUP(G13,DATABASE!$A$2:$A$809,DATABASE!$C$2:$C$809)} -> SPP ONLINE | E13: TELKOM VPN IP | F13: EKSISTING | G13: 4700020-0029217410 | H13: 202512 | I13: 512 Kbps | L13: 10.240.0.2 /30 | M13: 42440 | O13: 0.07125 | Q13: =(O13*24*3600*30/8)/100000 -> 0.23085 | R13: =(P13*24*3600*30/8)/100000 -> 0 | S13: 0 | T13: =(V13-S13)/V13*100% -> 1 | U13: 0.99 | V13: 2678400 | W13: =MAX(0, (((S13 - ((1 - VALUE(U13)) * V13)) / V13) * AE13)) -> 0 | X13: 0.00 | Y13: 2319819 | AE13: =SUM(Y13:AD13) -> 2319819 | AF13: =IFERROR(AE13+W13,0) -> 2319819
A14: =A13+1 -> 9 | B14: KANTOR PUSAT | C14: {=_xlfn.XLOOKUP(G14,DATABASE!$A$2:$A$806,DATABASE!$B$2:$B$806)} -> Bank Jatim u/ Host To Host KTP-el Ditjen Dukcapil; DC Sigma Tangerang Lt.3 Wing timur, BSD Tangerang | D14: {=_xlfn.XLOOKUP(G14,DATABASE!$A$2:$A$809,DATABASE!$C$2:$C$809)} -> H2H | E14: TELKOM VPN IP | F14: EKSISTING | G14: 4700020-0029298844 | H14: 202512 | I14: 2 Mbps | L14: 10.240.0.6 /30 | M14: 4/13/2016 | O14: 12.9 | Q14: =(O14*24*3600*30/8)/100000 -> 41.796 | R14: =(P14*24*3600*30/8)/100000 -> 0 | S14: 0 | T14: =(V14-S14)/V14*100% -> 1 | U14: 0.99 | V14: 2678400 | W14: =MAX(0, (((S14 - ((1 - VALUE(U14)) * V14)) / V14) * AE14)) -> 0 | X14: 0.00 | Y14: 3671171 | AE14: =SUM(Y14:AD14) -> 3671171 | AF14: =IFERROR(AE14+W14,0) -> 3671171
A15: =A14+1 -> 10 | B15: KANTOR PUSAT | C15: {=_xlfn.XLOOKUP(G15,DATABASE!$A$2:$A$806,DATABASE!$B$2:$B$806)} -> Bank Jatim u/ Host To Host Call Center Infomedia; Jl. A. Yani 88, Lt.4, Surabaya | D15: {=_xlfn.XLOOKUP(G15,DATABASE!$A$2:$A$809,DATABASE!$C$2:$C$809)} -> CALL CENTER INFOMEDIA | E15: TELKOM VPN IP | F15: EKSISTING | G15: 4700020-0030913016 | H15: 202512 | I15: 10 Mbps | L15: 192.168.151.174 /30 | M15: 5/26/2017 | O15: 6.44 | Q15: =(O15*24*3600*30/8)/100000 -> 20.8656 | R15: =(P15*24*3600*30/8)/100000 -> 0 | S15: 0 | T15: =(V15-S15)/V15*100% -> 1 | U15: 0.99 | V15: 2678400 | W15: =MAX(0, (((S15 - ((1 - VALUE(U15)) * V15)) / V15) * AE15)) -> 0 | X15: 0.00 | Y15: 9800000 | AE15: =SUM(Y15:AD15) -> 9800000 | AF15: =IFERROR(AE15+W15,0) -> 9800000
A16: =A15+1 -> 11 | B16: KANTOR PUSAT | C16: {=_xlfn.XLOOKUP(G16,DATABASE!$A$2:$A$806,DATABASE!$B$2:$B$806)} -> Bank Jatim u/ Internet DRC Bank Jatim; JL.Citraland Surabaya ( Astinet ) | D16: {=_xlfn.XLOOKUP(G16,DATABASE!$A$2:$A$809,DATABASE!$C$2:$C$809)} -> INTERNET KANTOR PUSAT | E16: TELKOM ASTINET | F16: EKSISTING | G16: 4700020-0031230943 | H16: 202512 | I16: 12 Mbps | L16: 172.17.171.38 /30 (36.89.37.209 /28) | M16: 12/29/2017 | O16: 515.17 | Q16: =(O16*24*3600*30/8)/100000 -> 1669.1508 | R16: =(P16*24*3600*30/8)/100000 -> 0 | S16: 0 | T16: =(V16-S16)/V16*100% -> 1 | U16: 0.99 | V16: 2678400 | W16: =MAX(0, (((S16 - ((1 - VALUE(U16)) * V16)) / V16) * AE16)) -> 0 | X16: 0.00 | Y16: 2940000 | AE16: =SUM(Y16:AD16) -> 2940000 | AF16: =IFERROR(AE16+W16,0) -> 2940000
A17: =A16+1 -> 12 | B17: KANTOR PUSAT | C17: {=_xlfn.XLOOKUP(G17,DATABASE!$A$2:$A$806,DATABASE!$B$2:$B$806)} -> Bank Jatim Backhaul VPN IP DC; Graha Telkom Sigma Lt 3 BSD Tangerang | D17: {=_xlfn.XLOOKUP(G17,DATABASE!$A$2:$A$809,DATABASE!$C$2:$C$809)} -> DC | E17: TELKOM VPN IP | F17: EKSISTING | G17: 4700020-82572 | H17: 202512 | I17: 100 Mbps | L17: 172.17.20.2 /30 | M17: 42186 | N17: 46022 | O17: 30904.32 | Q17: =(O17*24*3600*30/8)/100000 -> 100130 | R17: =(P17*24*3600*30/8)/100000 -> 0 | S17: 0 | T17: =(V17-S17)/V17*100% -> 1 | U17: 0.99 | V17: 2678400 | W17: =MAX(0, (((S17 - ((1 - VALUE(U17)) * V17)) / V17) * AE17)) -> 0 | X17: 0.00 | Y17: 20776000 | AE17: =SUM(Y17:AD17) -> 20776000 | AF17: =IFERROR(AE17+W17,0) -> 20776000 | AI17: Upgrade Bandwidth Temporer kegiatan akhir tahun 2025, Tidak merubah abonemen
A18: =A17+1 -> 13 | B18: KANTOR PUSAT | C18: {=_xlfn.XLOOKUP(G18,DATABASE!$A$2:$A$806,DATABASE!$B$2:$B$806)} -> Bank Jatim Backhaul VPN IP DRC; Bukit Bali B3-2 Lakarsantri Surabaya | D18: {=_xlfn.XLOOKUP(G18,DATABASE!$A$2:$A$809,DATABASE!$C$2:$C$809)} -> DRC | E18: TELKOM VPN IP | F18: EKSISTING | G18: 4700020-68390 | H18: 202512 | I18: 100 Mbps | L18: 172.17.52.2 /30 | M18: 6/24/2015 | O18: 26818.56 | Q18: =(O18*24*3600*30/8)/100000 -> 86892.134 | R18: =(P18*24*3600*30/8)/100000 -> 0 | S18: 0 | T18: =(V18-S18)/V18*100% -> 1 | U18: 0.99 | V18: 2678400 | W18: =MAX(0, (((S18 - ((1 - VALUE(U18)) * V18)) / V18) * AE18)) -> 0 | X18: 0.00 | Y18: 20776000 | AE18: =SUM(Y18:AD18) -> 20776000 | AF18: =IFERROR(AE18+W18,0) -> 20776000
A19: =A18+1 -> 14 | B19: KANTOR PUSAT | C19: {=_xlfn.XLOOKUP(G19,DATABASE!$A$2:$A$806,DATABASE!$B$2:$B$806)} -> Bank Jatim u/ Host To Host Metro DJP-DC; Jl. Gatot Subroto Kav. 40-42 JKT ke DC Sigma Citraland SBY (E-Filling) | D19: {=_xlfn.XLOOKUP(G19,DATABASE!$A$2:$A$809,DATABASE!$C$2:$C$809)} -> H2H METRO | E19: TELKOM METRO | F19: EKSISTING | G19: 4700020-0029669221 | H19: 202512 | I19: 1 Mbps | L19: - | M19: 1/26/2016 | O19: 3.91 | Q19: =(O19*24*3600*30/8)/100000 -> 12.6684 | R19: =(P19*24*3600*30/8)/100000 -> 0 | S19: 0 | T19: =(V19-S19)/V19*100% -> 1 | U19: 0.99 | V19: 2678400 | W19: =MAX(0, (((S19 - ((1 - VALUE(U19)) * V19)) / V19) * AE19)) -> 0 | X19: 0.00 | Y19: 2737114 | AE19: =SUM(Y19:AD19) -> 2737114 | AF19: =IFERROR(AE19+W19,0) -> 2737114
A20: =A19+1 -> 15 | B20: KANTOR PUSAT | C20: {=_xlfn.XLOOKUP(G20,DATABASE!$A$2:$A$806,DATABASE!$B$2:$B$806)} -> Bank Jatim u/ Host To Host Metro DC -DJP; DC Sigma Citraland SBY ke Jl. Gatot Subroto Kav. 40-42 JKT (E-Filling) | D20: {=_xlfn.XLOOKUP(G20,DATABASE!$A$2:$A$809,DATABASE!$C$2:$C$809)} -> H2H METRO | E20: TELKOM METRO | F20: EKSISTING | G20: 4700020-0030871897 | H20: 202512 | I20: 1 Mbps | L20: - | M20: 4/18/2017 | O20: 0.47008 | Q20: =(O20*24*3600*30/8)/100000 -> 1.5230592 | R20: =(P20*24*3600*30/8)/100000 -> 0 | S20: 0 | T20: =(V20-S20)/V20*100% -> 1 | U20: 0.99 | V20: 2678400 | W20: =MAX(0, (((S20 - ((1 - VALUE(U20)) * V20)) / V20) * AE20)) -> 0 | X20: 0.00 | Y20: 2737114 | AE20: =SUM(Y20:AD20) -> 2737114 | AF20: =IFERROR(AE20+W20,0) -> 2737114
A21: =A20+1 -> 16 | B21: KANTOR PUSAT | C21: {=_xlfn.XLOOKUP(G21,DATABASE!$A$2:$A$806,DATABASE!$B$2:$B$806)} -> Bank Jatim u/ Host To Host Metro Asabri -DC; Jl.Mayjen Sutoyo 11 JakTim | D21: {=_xlfn.XLOOKUP(G21,DATABASE!$A$2:$A$809,DATABASE!$C$2:$C$809)} -> H2H METRO | E21: TELKOM METRO | F21: EKSISTING | G21: 4700020-0031134693 | H21: 202512 | I21: 1 Mbps | L21: - | M21: 10/26/2017 | O21: 114.11 | Q21: =(O21*24*3600*30/8)/100000 -> 369.7164 | R21: =(P21*24*3600*30/8)/100000 -> 0 | S21: 0 | T21: =(V21-S21)/V21*100% -> 1 | U21: 0.99 | V21: 2678400 | W21: =MAX(0, (((S21 - ((1 - VALUE(U21)) * V21)) / V21) * AE21)) -> 0 | X21: 0.00 | Y21: 2737114 | AE21: =SUM(Y21:AD21) -> 2737114 | AF21: =IFERROR(AE21+W21,0) -> 2737114
A22: =A21+1 -> 17 | B22: KANTOR PUSAT | C22: {=_xlfn.XLOOKUP(G22,DATABASE!$A$2:$A$806,DATABASE!$B$2:$B$806)} -> Bank Jatim u/ Host To Host Metro DC- Asabri; Sigma Citraland Jl.Bukit Bali B3 2 Lakarsantri Surabaya | D22: {=_xlfn.XLOOKUP(G22,DATABASE!$A$2:$A$809,DATABASE!$C$2:$C$809)} -> H2H METRO | E22: TELKOM METRO | F22: EKSISTING | G22: 4700020-0031135108 | H22: 202512 | I22: 1 Mbps | L22: - | M22: 10/31/2017 | O22: 0.48568 | Q22: =(O22*24*3600*30/8)/100000 -> 1.5736032 | R22: =(P22*24*3600*30/8)/100000 -> 0 | S22: 0 | T22: =(V22-S22)/V22*100% -> 1 | U22: 0.99 | V22: 2678400 | W22: =MAX(0, (((S22 - ((1 - VALUE(U22)) * V22)) / V22) * AE22)) -> 0 | X22: 0.00 | Y22: 2737114 | AE22: =SUM(Y22:AD22) -> 2737114 | AF22: =IFERROR(AE22+W22,0) -> 2737114
A23: =A22+1 -> 18 | B23: KANTOR PUSAT | C23: {=_xlfn.XLOOKUP(G23,DATABASE!$A$2:$A$806,DATABASE!$B$2:$B$806)} -> Bank Jatim u/ Host To Host Metro P2P DC-MKM; Data Center Jl. Gedung German Center Lt. 3, BSD Tangerang ke DCI Bekasi (H2H MKM DCI Tangerang) | D23: {=_xlfn.XLOOKUP(G23,DATABASE!$A$2:$A$809,DATABASE!$C$2:$C$809)} -> H2H METRO | E23: TELKOM METRO | F23: EKSISTING | G23: 790038103 | H23: 202512 | I23: 1 Mbps | L23: - | M23: 43497 | O23: 68.86 | Q23: =(O23*24*3600*30/8)/100000 -> 223.1064 | R23: =(P23*24*3600*30/8)/100000 -> 0 | S23: 0 | T23: =(V23-S23)/V23*100% -> 1 | U23: 0.99 | V23: 2678400 | W23: =MAX(0, (((S23 - ((1 - VALUE(U23)) * V23)) / V23) * AE23)) -> 0 | X23: 0.00 | Y23: 2737114 | AE23: =SUM(Y23:AD23) -> 2737114 | AF23: =IFERROR(AE23+W23,0) -> 2737114
A24: =A23+1 -> 19 | B24: KANTOR PUSAT | C24: {=_xlfn.XLOOKUP(G24,DATABASE!$A$2:$A$806,DATABASE!$B$2:$B$806)} -> Bank Jatim u/ Host To Host Metro P2P MKM-DC; DCI Bekasi, Jl. Halmahera Blok F1 No.1, Danau Indah, Cikarang Bar, Bekasi ke (H2H MKM DCI Tangerang) | D24: {=_xlfn.XLOOKUP(G24,DATABASE!$A$2:$A$809,DATABASE!$C$2:$C$809)} -> H2H METRO | E24: TELKOM METRO | F24: EKSISTING | G24: 790226991 | H24: 202512 | I24: 1 Mbps | L24: - | M24: 43497 | O24: 34.65 | Q24: =(O24*24*3600*30/8)/100000 -> 112.266 | R24: =(P24*24*3600*30/8)/100000 -> 0 | S24: 0 | T24: =(V24-S24)/V24*100% -> 1 | U24: 0.99 | V24: 2678400 | W24: =MAX(0, (((S24 - ((1 - VALUE(U24)) * V24)) / V24) * AE24)) -> 0 | X24: 0.00 | Y24: 2737114 | AE24: =SUM(Y24:AD24) -> 2737114 | AF24: =IFERROR(AE24+W24,0) -> 2737114
A25: =A24+1 -> 20 | B25: KANTOR PUSAT | C25: {=_xlfn.XLOOKUP(G25,DATABASE!$A$2:$A$806,DATABASE!$B$2:$B$806)} -> Bank Jatim u/ Host To Host Metro Bpjs T.Kerja JL. Medan Merdeka Barat 13-14, Jakarta Pusat | D25: {=_xlfn.XLOOKUP(G25,DATABASE!$A$2:$A$809,DATABASE!$C$2:$C$809)} -> H2H METRO | E25: TELKOM METRO | F25: EKSISTING | G25: 1261472344 | H25: 202512 | I25: 1 Mbps | L25: - | M25: 3/26/2021 | O25: 0.62455 | Q25: =(O25*24*3600*30/8)/100000 -> 2.023542 | R25: =(P25*24*3600*30/8)/100000 -> 0 | S25: 0 | T25: =(V25-S25)/V25*100% -> 1 | U25: 0.99 | V25: 2678400 | W25: =MAX(0, (((S25 - ((1 - VALUE(U25)) * V25)) / V25) * AE25)) -> 0 | X25: 0.00 | Y25: 2737114 | AE25: =SUM(Y25:AD25) -> 2737114 | AF25: =IFERROR(AE25+W25,0) -> 2737114
A26: =A25+1 -> 21 | B26: KANTOR PUSAT | C26: {=_xlfn.XLOOKUP(G26,DATABASE!$A$2:$A$806,DATABASE!$B$2:$B$806)} -> Bank Jatim u/ Host To Host Metro BPJS Graha Sigma Lt.6, Tangerang | D26: {=_xlfn.XLOOKUP(G26,DATABASE!$A$2:$A$809,DATABASE!$C$2:$C$809)} -> H2H METRO | E26: TELKOM METRO | F26: EKSISTING | G26: 1261472394 | H26: 202512 | I26: 1 Mbps | L26: - | M26: 3/26/2021 | O26: 789.32 | Q26: =(O26*24*3600*30/8)/100000 -> 2557.3968 | R26: =(P26*24*3600*30/8)/100000 -> 0 | S26: 0 | T26: =(V26-S26)/V26*100% -> 1 | U26: 0.99 | V26: 2678400 | W26: =MAX(0, (((S26 - ((1 - VALUE(U26)) * V26)) / V26) * AE26)) -> 0 | X26: 0.00 | Y26: 2737114 | AE26: =SUM(Y26:AD26) -> 2737114 | AF26: =IFERROR(AE26+W26,0) -> 2737114
A27: =A26+1 -> 22 | B27: KANTOR PUSAT | C27: {=_xlfn.XLOOKUP(G27,DATABASE!$A$2:$A$806,DATABASE!$B$2:$B$806)} -> Bank Jatim u/ Aplikasi JKD BANK INDONESIA JL. Kapten Subijanto LT. 5, German Center BSD Tangerang Selatan | D27: {=_xlfn.XLOOKUP(G27,DATABASE!$A$2:$A$809,DATABASE!$C$2:$C$809)} -> JKD BI | E27: TELKOM MANAGED NETWORK | F27: EKSISTING | G27: 1707535922 | H27: 202512 | I27: 0 | L27: - | M27: 43717 | O27: 0 | Q27: =(O27*24*3600*30/8)/100000 -> 0 | R27: =(P27*24*3600*30/8)/100000 -> 0 | S27: 0 | T27: =(V27-S27)/V27*100% -> 1 | U27: 0.99 | V27: 2678400 | W27: =MAX(0, (((S27 - ((1 - VALUE(U27)) * V27)) / V27) * AE27)) -> 0 | X27: 0.00 | Y27: 1412612 | AE27: =SUM(Y27:AD27) -> 1412612 | AF27: =IFERROR(AE27+W27,0) -> 1412612
A28: =A27+1 -> 23 | B28: KANTOR PUSAT | C28: {=_xlfn.XLOOKUP(G28,DATABASE!$A$2:$A$809,DATABASE!$B$2:$B$809)} -> Cabang Balikpapan JL. Jend Sudirman No.02 RT 011 Kel.Damai, Balikpapan Kaltim | D28: {=_xlfn.XLOOKUP(G28,DATABASE!$A$2:$A$809,DATABASE!$C$2:$C$809)} -> CABANG | E28: TELKOM VPN IP | F28: EKSISTING | G28: 2092109850 | H28: 202512 | I28: 2 Mbps | L28: 192.168.170.2/30 | M28: 45968 | O28: 12.40875 | Q28: =(O28*24*3600*30/8)/100000 -> 40.20435 | R28: =(P28*24*3600*30/8)/100000 -> 0 | S28: 0 | T28: =(V28-S28)/V28 -> 1 | U28: 0.99 | V28: 2678400 | W28: =MAX(0, (((S28 - ((1 - VALUE(U28)) * V28)) / V28) * AE28)) -> 0 | X28: 0.00 | Y28: 3671171 | AE28: =SUM(Y28:AD28) -> 3671171 | AF28: =IFERROR(AE28+W28,0) -> 3671171
A29: =A28+1 -> 24 | B29: UTAMA | C29: {=_xlfn.XLOOKUP(G29,DATABASE!$A$2:$A$806,DATABASE!$B$2:$B$806)} -> Kantor Kas Pajak Online Pemkot Surabaya, Jimerto 25-27 | D29: {=_xlfn.XLOOKUP(G29,DATABASE!$A$2:$A$809,DATABASE!$C$2:$C$809)} -> KANTOR KAS | E29: TELKOM VPN IP | F29: EKSISTING | G29: 4700020-88376 | H29: 202512 | I29: 512 Kbps | L29: 192.168.151.18 /30 | M29: 9/22/2017 | O29: 12.06 | Q29: =(O29*24*3600*30/8)/100000 -> 39.0744 | R29: =(P29*24*3600*30/8)/100000 -> 0 | S29: 300 | T29: =(V29-S29)/V29*100% -> 0.99988799 | U29: 0.99 | V29: 2678400 | W29: =MAX(0, (((S29 - ((1 - VALUE(U29)) * V29)) / V29) * AE29)) -> 0 | X29: 0.00 | Y29: 2319819 | AE29: =SUM(Y29:AD29) -> 2319819 | AF29: =IFERROR(AE29+W29,0) -> 2319819 | AG29: 99316968
A30: =A29+1 -> 25 | B30: UTAMA | C30: {=_xlfn.XLOOKUP(G30,DATABASE!$A$2:$A$806,DATABASE!$B$2:$B$806)} -> Kantor Kas Provinsi Jatim - Gubernur, Johar 17 Surabaya | D30: {=_xlfn.XLOOKUP(G30,DATABASE!$A$2:$A$809,DATABASE!$C$2:$C$809)} -> KANTOR KAS | E30: TELKOM VPN IP | F30: EKSISTING | G30: 4700020-88369 | H30: 202512 | I30: 512 Kbps | L30: 192.168.151.182 /30 | M30: 43773 | O30: 0.00203 | Q30: =(O30*24*3600*30/8)/100000 -> 0.0065772 | R30: =(P30*24*3600*30/8)/100000 -> 0 | S30: 420 | T30: =(V30-S30)/V30*100% -> 0.99984319 | U30: 0.99 | V30: 2678400 | W30: =MAX(0, (((S30 - ((1 - VALUE(U30)) * V30)) / V30) * AE30)) -> 0 | X30: 0.00 | Y30: 2319819 | AE30: =SUM(Y30:AD30) -> 2319819 | AF30: =IFERROR(AE30+W30,0) -> 2319819
A31: =A30+1 -> 26 | B31: UTAMA | C31: {=_xlfn.XLOOKUP(G31,DATABASE!$A$2:$A$806,DATABASE!$B$2:$B$806)} -> Kantor Kas Dipenda Manyar, Manyar Kertoarjo | D31: {=_xlfn.XLOOKUP(G31,DATABASE!$A$2:$A$809,DATABASE!$C$2:$C$809)} -> KANTOR KAS | E31: TELKOM VPN IP | F31: EKSISTING | G31: 4700020-88373 | H31: 202512 | I31: 512 Kbps | L31: 192.168.150.10 /30 | M31: 6/24/2015 | O31: 5.24 | Q31: =(O31*24*3600*30/8)/100000 -> 16.9776 | R31: =(P31*24*3600*30/8)/100000 -> 0 | S31: 7860 | T31: =(V31-S31)/V31*100% -> 0.99706541 | U31: 0.99 | V31: 2678400 | W31: =MAX(0, (((S31 - ((1 - VALUE(U31)) * V31)) / V31) * AE31)) -> 0 | X31: 0.00 | Y31: 2319819 | AE31: =SUM(Y31:AD31) -> 2319819 | AF31: =IFERROR(AE31+W31,0) -> 2319819
A32: =A31+1 -> 27 | B32: UTAMA | C32: {=_xlfn.XLOOKUP(G32,DATABASE!$A$2:$A$806,DATABASE!$B$2:$B$806)} -> Samsat Online Capem UWK (Univ. Wijaya Kusuma), Dukuh Kupang Barat 1 | D32: {=_xlfn.XLOOKUP(G32,DATABASE!$A$2:$A$809,DATABASE!$C$2:$C$809)} -> SAMSAT ONLINE | E32: TELKOM VPN IP | F32: EKSISTING | G32: 4700020-28893 | H32: 202512 | I32: 256 Kbps | L32: 172.200.15.1 /24 | M32: 42156 | O32: 0.15924 | Q32: =(O32*24*3600*30/8)/100000 -> 0.5159376 | R32: =(P32*24*3600*30/8)/100000 -> 0 | S32: 0 | T32: =(V32-S32)/V32*100% -> 1 | U32: 0.99 | V32: 2678400 | W32: =MAX(0, (((S32 - ((1 - VALUE(U32)) * V32)) / V32) * AE32)) -> 0 | X32: 0.00 | Y32: 1950000 | AE32: =SUM(Y32:AD32) -> 1950000 | AF32: =IFERROR(AE32+W32,0) -> 1950000
A33: =A32+1 -> 28 | B33: UTAMA | C33: {=_xlfn.XLOOKUP(G33,DATABASE!$A$2:$A$806,DATABASE!$B$2:$B$806)} -> UPTB 1 Tambakrejo. Jl.Tambak Rejo 5/1 Surabaya | D33: {=_xlfn.XLOOKUP(G33,DATABASE!$A$2:$A$809,DATABASE!$C$2:$C$809)} -> UPTB | E33: TELKOM VPN IP | F33: EKSISTING | G33: 1113954367 | H33: 202512 | I33: 512 Kbps | L33: 196.168.107.193 /29 | M33: 11/25/2019 | O33: 0.33927 | Q33: =(O33*24*3600*30/8)/100000 -> 1.0992348 | R33: =(P33*24*3600*30/8)/100000 -> 0 | S33: 0 | T33: =(V33-S33)/V33*100% -> 1 | U33: 0.99 | V33: 2678400 | W33: =MAX(0, (((S33 - ((1 - VALUE(U33)) * V33)) / V33) * AE33)) -> 0 | X33: 0.00 | Y33: 2319819 | AE33: =SUM(Y33:AD33) -> 2319819 | AF33: =IFERROR(AE33+W33,0) -> 2319819
A34: =A33+1 -> 29 | B34: UTAMA | C34: {=_xlfn.XLOOKUP(G34,DATABASE!$A$2:$A$806,DATABASE!$B$2:$B$806)} -> UPTB 4 Dukuh Kupang, Dukuh Kupang 1/25 Surabaya | D34: {=_xlfn.XLOOKUP(G34,DATABASE!$A$2:$A$809,DATABASE!$C$2:$C$809)} -> UPTB | E34: TELKOM VPN IP | F34: EKSISTING | G34: 1155255333 | H34: 202512 | I34: 512 Kbps | L34: 196.168.107.169 /29 | M34: 43864 | O34: 0.51197 | Q34: =(O34*24*3600*30/8)/100000 -> 1.6587828 | R34: =(P34*24*3600*30/8)/100000 -> 0 | S34: 0 | T34: =(V34-S34)/V34*100% -> 1 | U34: 0.99 | V34: 2678400 | W34: =MAX(0, (((S34 - ((1 - VALUE(U34)) * V34)) / V34) * AE34)) -> 0 | X34: 0.00 | Y34: 2319819 | AE34: =SUM(Y34:AD34) -> 2319819 | AF34: =IFERROR(AE34+W34,0) -> 2319819
A35: =A34+1 -> 30 | B35: UTAMA | C35: {=_xlfn.XLOOKUP(G35,DATABASE!$A$2:$A$806,DATABASE!$B$2:$B$806)} -> UPTB 5 Manyar , Sukadami 1 Surabaya | D35: {=_xlfn.XLOOKUP(G35,DATABASE!$A$2:$A$809,DATABASE!$C$2:$C$809)} -> UPTB | E35: TELKOM VPN IP | F35: EKSISTING | G35: 1148350816 | H35: 202512 | I35: 512 Kbps | L35: 196.168.107.161 /29 | M35: 1/27/2020 | O35: 0.35557 | Q35: =(O35*24*3600*30/8)/100000 -> 1.1520468 | R35: =(P35*24*3600*30/8)/100000 -> 0 | S35: 0 | T35: =(V35-S35)/V35*100% -> 1 | U35: 0.99 | V35: 2678400 | W35: =MAX(0, (((S35 - ((1 - VALUE(U35)) * V35)) / V35) * AE35)) -> 0 | X35: 0.00 | Y35: 2319819 | AE35: =SUM(Y35:AD35) -> 2319819 | AF35: =IFERROR(AE35+W35,0) -> 2319819
A36: =A35+1 -> 31 | B36: UTAMA | C36: {=_xlfn.XLOOKUP(G36,DATABASE!$A$2:$A$806,DATABASE!$B$2:$B$806)} -> UPTB 8 Rungkut Asri , Rungkut Asri Timur XVIII/2 Surabaya | D36: {=_xlfn.XLOOKUP(G36,DATABASE!$A$2:$A$809,DATABASE!$C$2:$C$809)} -> UPTB | E36: TELKOM VPN IP | F36: EKSISTING | G36: 1151434694 | H36: 202512 | I36: 512 Kbps | L36: 196.168.107.153 /29 | M36: 43864 | O36: 0.33537 | Q36: =(O36*24*3600*30/8)/100000 -> 1.0865988 | R36: =(P36*24*3600*30/8)/100000 -> 0 | S36: 0 | T36: =(V36-S36)/V36*100% -> 1 | U36: 0.99 | V36: 2678400 | W36: =MAX(0, (((S36 - ((1 - VALUE(U36)) * V36)) / V36) * AE36)) -> 0 | X36: 0.00 | Y36: 2319819 | AE36: =SUM(Y36:AD36) -> 2319819 | AF36: =IFERROR(AE36+W36,0) -> 2319819
A37: =A36+1 -> 32 | B37: UTAMA | C37: {=_xlfn.XLOOKUP(G37,DATABASE!$A$2:$A$806,DATABASE!$B$2:$B$806)} -> Capem Tambakrejo, Jl.Kapas Krampung 69 Tambakrejo | D37: {=_xlfn.XLOOKUP(G37,DATABASE!$A$2:$A$809,DATABASE!$C$2:$C$809)} -> CAPEM | E37: TELKOM VPN IP | F37: EKSISTING | G37: 4700020-06007 | H37: 202512 | I37: 1 Mbps | L37: 192.168.152.170 /30 | M37: 42156 | O37: 22.23 | Q37: =(O37*24*3600*30/8)/100000 -> 72.0252 | R37: =(P37*24*3600*30/8)/100000 -> 0 | S37: 0 | T37: =(V37-S37)/V37*100% -> 1 | U37: 0.99 | V37: 2678400 | W37: =MAX(0, (((S37 - ((1 - VALUE(U37)) * V37)) / V37) * AE37)) -> 0 | X37: 0.00 | Y37: 2792792 | AE37: =SUM(Y37:AD37) -> 2792792 | AF37: =IFERROR(AE37+W37,0) -> 2792792
A38: =A37+1 -> 33 | B38: UTAMA | C38: {=_xlfn.XLOOKUP(G38,DATABASE!$A$2:$A$806,DATABASE!$B$2:$B$806)} -> ATM RSAL, Jl.Gadung 1 Surabaya | D38: {=_xlfn.XLOOKUP(G38,DATABASE!$A$2:$A$809,DATABASE!$C$2:$C$809)} -> ATM | E38: TELKOM VPN IP | F38: EKSISTING | G38: 4700020-07944 | H38: 202512 | I38: 128 Kbps | L38: 196.168.107.73 /29 | M38: 43286 | O38: 10.66 | Q38: =(O38*24*3600*30/8)/100000 -> 34.5384 | R38: =(P38*24*3600*30/8)/100000 -> 0 | S38: 0 | T38: =(V38-S38)/V38*100% -> 1 | U38: 0.99 | V38: 2678400 | W38: =MAX(0, (((S38 - ((1 - VALUE(U38)) * V38)) / V38) * AE38)) -> 0 | X38: 0.00 | Y38: 1300000 | AE38: =SUM(Y38:AD38) -> 1300000 | AF38: =IFERROR(AE38+W38,0) -> 1300000
A39: =A38+1 -> 34 | B39: UTAMA | C39: {=_xlfn.XLOOKUP(G39,DATABASE!$A$2:$A$806,DATABASE!$B$2:$B$806)} -> Payment Point RS Soewandi Jl. Tambakrejo No. 45-47 | D39: {=_xlfn.XLOOKUP(G39,DATABASE!$A$2:$A$809,DATABASE!$C$2:$C$809)} -> PAYMENT POINT | E39: TELKOM VPN IP | F39: EKSISTING | G39: 4700020-0020374118 | H39: 202512 | I39: 512 Kbps | L39: 196.168.168.65 /29 | M39: 4/24/2021 | O39: 0.21863 | Q39: =(O39*24*3600*30/8)/100000 -> 0.7083612 | R39: =(P39*24*3600*30/8)/100000 -> 0 | S39: 0 | T39: =(V39-S39)/V39*100% -> 1 | U39: 0.99 | V39: 2678400 | W39: =MAX(0, (((S39 - ((1 - VALUE(U39)) * V39)) / V39) * AE39)) -> 0 | X39: 0.00 | Y39: 2319819 | AE39: =SUM(Y39:AD39) -> 2319819 | AF39: =IFERROR(AE39+W39,0) -> 2319819
A40: =A39+1 -> 35 | B40: UTAMA | C40: {=_xlfn.XLOOKUP(G40,DATABASE!$A$2:$A$806,DATABASE!$B$2:$B$806)} -> Host To Host Sistem Administrasi Manunggal Satu Atap MANYAR, Dipenda, Manyar Kertoarjo | D40: {=_xlfn.XLOOKUP(G40,DATABASE!$A$2:$A$809,DATABASE!$C$2:$C$809)} -> H2H | E40: TELKOM VPN IP | F40: EKSISTING | G40: 4700020-13201 | H40: 202512 | I40: 1 Mbps | L40: 192.168.153.194 /30 | M40: 42186 | O40: 3.76 | Q40: =(O40*24*3600*30/8)/100000 -> 12.1824 | R40: =(P40*24*3600*30/8)/100000 -> 0 | S40: 0 | T40: =(V40-S40)/V40*100% -> 1 | U40: 0.99 | V40: 2678400 | W40: =MAX(0, (((S40 - ((1 - VALUE(U40)) * V40)) / V40) * AE40)) -> 0 | X40: 0.00 | Y40: 2792792 | AE40: =SUM(Y40:AD40) -> 2792792 | AF40: =IFERROR(AE40+W40,0) -> 2792792
A41: =A40+1 -> 36 | B41: UTAMA | C41: {=_xlfn.XLOOKUP(G41,DATABASE!$A$2:$A$806,DATABASE!$B$2:$B$806)} -> Host To Host & Anjungan Tunai Mandiri UWK, Dukuh Kupang Barat 1 | D41: {=_xlfn.XLOOKUP(G41,DATABASE!$A$2:$A$809,DATABASE!$C$2:$C$809)} -> H2H | E41: TELKOM VPN IP | F41: EKSISTING | G41: 4700020-08485 | H41: 202512 | I41: 512 Kbps | L41: 172.27.20.17 /30 | M41: 42278 | O41: 5.95 | Q41: =(O41*24*3600*30/8)/100000 -> 19.278 | R41: =(P41*24*3600*30/8)/100000 -> 0 | S41: 0 | T41: =(V41-S41)/V41*100% -> 1 | U41: 0.99 | V41: 2678400 | W41: =MAX(0, (((S41 - ((1 - VALUE(U41)) * V41)) / V41) * AE41)) -> 0 | X41: 0.00 | Y41: 2319819 | AE41: =SUM(Y41:AD41) -> 2319819 | AF41: =IFERROR(AE41+W41,0) -> 2319819
...

Sheet Summary JAN26
B2: INVOICE PERIODE JANUARI 2026
B4: *TELKOM - MONTHLY DATA SUMMARY
B6: KATEGORI | C6: TOTAL TITIK | D6: TOTAL NILAI
B7: A. LAYANAN EKSISTING
B8: Total Layanan Eksisting | C8: =COUNTIF('JAN26'!F5:F796, "*EKSISTING*") -> 779 | D8: =SUM('JAN26'!Y5:Y796) -> 1840755777
B9: B. LAYANAN BARU (PSB)
B10: Total Layanan Baru (PSB) | C10: =COUNTIF('JAN26'!F5:F796, "*PASANG BARU*") -> 2 | D10: =SUM('JAN26'!AC5:AC793) -> 1981982
B11: C. LAYANAN RELOKASI
B12: Total Layanan Relokasi | C12: =COUNTIF('JAN26'!F5:F793, "*RELOKASI*") -> 5 | D12: =SUM('JAN26'!AD5:AD793) -> 0
B13: D. LAYANAN UPGRADE
B14: Total Layanan Upgrade | C14: =COUNTIF('JAN26'!F5:F793, "*UPGRADE*") -> 0 | D14: =SUM('JAN26'!Z5:Z793) -> 0
B15: E. LAYANAN DOWNGRADE
B16: Total Layanan Downgrade | C16: =COUNTIF('JAN26'!F5:F793, "*DOWNGRADE*") -> 0 | D16: =SUM('JAN26'!AA5:AA793) -> 0
B17: F. CABUT/ PEMUTUSAN JARINGAN
B18: Total Cabut/ Pemutusan Jaringan | C18: =COUNTIF('JAN26'!F5:F793, "*PEMUTUSAN*") -> 5 | D18: =SUM('JAN26'!AB5:AB793) -> 5822339
B19: Total Nilai Tagihan | C19: =SUM(C8:C18) -> 791 | D19: =SUM(D8:D18) -> 1848560098
B20: G. Total Titik Lokasi SLA Yang Terpenuhi | D20: =SUMPRODUCT(--(IFERROR(ROUND(VALUE(TRIM('JAN26'!$T$5:$T$797)), 4), 0) >= 0.99)) -> 788
B21: H. Total Titik Lokasi SLA Yang Tidak Terpenuhi | D21: =COUNTIF('JAN26'!T5:T797, "<99%") -> 3
B22: I. Total Nilai Restitusi SLA Yang Tidak Terpenuhi | D22: -183108
B23: J.Total Nilai Restitusi Tagihan | D23: =SUM('JAN26'!X5:X795) -> 0
B24: Total Nilai Tagihan Setelah Restitusi | D24: =D19+D22+D23 -> 1848376990
B25: PPN | D25: =D24*0.11 -> 2.0332147e+08
B26: Grand Total Nilai Tagihan | D26: =SUM(D24:D25) -> 2051698459

Sheet Data Invois Jan26 (791)
C1: TAGIHAN PERIODE JANUARI 2026
B2: • TELKOM - MONTHLY RECURRING CHARGES
A3: NO. | B3: JENIS KANTOR | C3: ALAMAT | D3: KATEGORI LOKASI | E3: LAYANAN | F3: TYPE ORDER | G3: ID | H3: PERIOD | I3: Bandwidth | L3: IP Host Telkom | M3: TANGGAL AKTIVASI | N3: TANGGAL MULAI AKTIF LAYANAN (UPGRADE/DOWNGRADE) | O3: PEMAKAIAN AVERAGE (Kbps) | Q3: TRAFFIK TOTAL (Kbps) | S3: DURASI DOWNTIME | T3: SLA | V3: AVAILABILITY (Jam/bulan) | W3: RESTITUSI (Rp) | Y3: HARGA (Rp) | AE3: TOTAL | AF3: HARGA SETELAH RESTITUSI | AG3: SUB TOTAL PER CABANG | AH3: MIKROTIK/NONMIKROTIK | AI3: KETERANGAN | AJ3: ID | AK3: BANDWIDTH INV vs BANDWIDTH NOJAR | AO3: HARGA INV vs HARGA Adendum II | AR3: SLA
G4: SID JAN 2026 | I4: Eksisting BW | J4: Upgrade BW | K4: Downgrade BW | O4: Eksisting | P4: Upgrade | Q4: Eksisting | R4: Upgrade | S4: (Jam) | T4: SLA ACTUAL | U4: SLA PKS | W4: Restitusi Over SLA | X4: Restitusi Tagihan | Y4: Eksisting | Z4: Upgrade (Prorate) | AA4: Downgrade (Prorate) | AB4: Cabut (Prorate) | AC4: PSB (Prorate) | AD4: Relokasi | AE4: TOTAL | AF4: HARGA SETELAH RESTITUSI | AG4: SUB TOTAL PER CABANG | AH4: MIKROTIK/NONMIKROTIK | AI4: KETERANGAN | AJ4: SID JAN | AK4: Eksisting BW | AL4: Upgrade BW | AM4: BW Nojar | AN4: Compare BW | AO4: Harga ADD II | AP4: Hasil Compare Harga | AQ4: KER HARGA | AR4: Hari | AS4: Jam | AT4: Menit | AU4: KET
A5: A | B5: B | C5: C | D5: D | E5: E | F5: F | G5: G | H5: H | I5: I | J5: J | K5: K | L5: L | M5: M | N5: N | O5: O | P5: P | Q5: Q | R5: R | S5: S | T5: T | U5: U | V5: V | W5: W | X5: X | Y5: Y | Z5: Z | AA5: AA | AB5: AB | AC5: AC | AD5: AD | AE5: AE | AF5: AE | AG5: AG | AH5: AH | AI5: AI | AJ5: G | AK5: I | AL5: J | AM5: BW | AN5: Compare | AO5: Harga | AP5: Compare | AQ5: KER HARGA | AR5: Hari | AS5: Jam | AT5: Menit | AU5: COMPARE
A6: 1 | B6: KANTOR PUSAT | C6: {=_xlfn.XLOOKUP(G6,DATABASE!$A$2:$A$806,DATABASE!$B$2:$B$806)} -> Bank Jatim Internet Kantor Pusat; Jl.Basuki Rahmat No. 98-104, Surabaya ( Astinet ) | D6: {=_xlfn.XLOOKUP(G6,DATABASE!$A$2:$A$808,DATABASE!$C$2:$C$808)} -> INTERNET KANTOR PUSAT | E6: TELKOM ASTINET | F6: EKSISTING | G6: 4700020-38090 | H6: 202512 | I6: 100 Mbps | L6: 10.10.30.1 /30 (222.124.169.177 /29) | M6: 7/26/2017 | N6: 46022 | O6: 12390.4 | Q6: =(O6*24*3600*30/8)/100000 -> 40144.896 | R6: =(P6*24*3600*30/8)/100000 -> 0 | S6: 0 | T6: =(V6-S6)/V6 -> 1 | U6: 0.99 | V6: 720 | W6: =IF(T6<99%,((S6-V6)/720)*Y6,0) -> 0 | X6: 0.00 | Y6: 20412151 | AE6: =SUM(Y6:AD6) -> 20412151 | AF6: =IFERROR(AE6+W6,0) -> 20412151 | AG6: 107313280 | AI6: Upgrade Bandwidth Temporer kegiatan akhir tahun 2025, Tidak merubah abonemen | AJ6: 4700020-38090 | AK6: 100 Mbps | AM6: =VLOOKUP(AJ6,'[1]Master Jaringan Des 2025(792)'!$D$2:$E$795,2,0) -> #REF! | AN6: =AM6=AK6 -> #REF! | AO6: 20412151 | AP6: =AO6=Y6 -> TRUE | AR6: =IFERROR(VLOOKUP(AX5,'[2]Availability Des25'!$C$5:$G$18,5,0),0) -> 0 | AS6: =IFERROR(VLOOKUP(AX5,'[2]Availability Des25'!$C$5:$H$18,6,0),0) -> 0 | AT6: =IFERROR(VLOOKUP(AX5,'[2]Availability Des25'!$C$5:$I$18,7,0),0) -> 0
A7: =A6+1 -> 2 | B7: KANTOR PUSAT | C7: {=_xlfn.XLOOKUP(G7,DATABASE!$A$2:$A$808,DATABASE!$B$2:$B$808)} -> Bank Jatim Backhaul VPN IP Kantor Pusat; Jl. Basuki Rahmat No 98-104 Surabaya | D7: {=_xlfn.XLOOKUP(G7,DATABASE!$A$2:$A$808,DATABASE!$C$2:$C$808)} -> WAN KANTOR PUSAT | E7: TELKOM VPN IP | F7: EKSISTING | G7: 4700020-10498 | H7: 202512 | I7: 100 Mbps | L7: 192.168.152.2 /30 | M7: 43199 | N7: 46022 | O7: 48363.52 | Q7: =(O7*24*3600*30/8)/100000 -> 156697.8 | R7: =(P7*24*3600*30/8)/100000 -> 0 | S7: 0 | T7: =(V7-S7)/V7*100% -> 1 | U7: 0.99 | V7: 720 | W7: =IF(T7<99%,((S7-V7)/720)*Y7,0) -> 0 | X7: 0.00 | Y7: 20776000 | AE7: =SUM(Y7:AD7) -> 20776000 | AF7: =IFERROR(AE7+W7,0) -> 20776000 | AI7: Upgrade Bandwidth Temporer kegiatan akhir tahun 2025, Tidak merubah abonemen | AJ7: 4700020-10498 | AK7: 100 Mbps | AM7: =VLOOKUP(AJ7,'[1]Master Jaringan Des 2025(792)'!$D$2:$E$795,2,0) -> #REF! | AN7: =AM7=AK7 -> #REF! | AO7: 20776000 | AP7: =AO7=Y7 -> TRUE | AR7: =IFERROR(VLOOKUP(AX6,'[2]Availability Des25'!$C$5:$G$18,5,0),0) -> 0 | AS7: =IFERROR(VLOOKUP(AX6,'[2]Availability Des25'!$C$5:$H$18,6,0),0) -> 0 | AT7: =IFERROR(VLOOKUP(AX6,'[2]Availability Des25'!$C$5:$I$18,7,0),0) -> 0
A8: =A7+1 -> 3 | B8: KANTOR PUSAT | C8: {=_xlfn.XLOOKUP(G8,DATABASE!$A$2:$A$806,DATABASE!$B$2:$B$806)} -> Bank Jatim Neucentrix Gubeng, Jl.Sumatera No.131 Lt 3 Kec Gubeng , Surabaya | D8: {=_xlfn.XLOOKUP(G8,DATABASE!$A$2:$A$808,DATABASE!$C$2:$C$808)} -> COLOCATION | E8: TELKOM NEUCENTRIX | F8: PASANG BARU | G8: 2095151855/2095149600 | H8: 202512 | I8: 20 Mbps | L8: 36.64.131.241/29 | M8: 46003 | N8: 46003 | O8: 234.11 | Q8: =(O8*24*3600*30/8)/100000 -> 758.5164 | R8: =(P8*24*3600*30/8)/100000 -> 0 | S8: 0 | T8: =(V8-S8)/V8*100% -> 1 | U8: 0.99 | V8: 720 | W8: =IF(T8<99%,((S8-V8)/720)*Y8,0) -> 0 | X8: 0.00 | Y8: 1377297 | AC8: 0 | AE8: =SUM(Y8:AD8) -> 1377297 | AF8: =IFERROR(AE8+W8,0) -> 1377297 | AI8: MIGRASI KE LAYANAN BARU dengan PASANG BARU DES 2025 | AJ8: 4700020-0003122034 | AK8: 256 Kbps | AM8: =VLOOKUP(AJ8,'[1]Master Jaringan Des 2025(792)'!$D$2:$E$795,2,0) -> #REF! | AN8: =AM8=AK8 -> #REF! | AO8: 2295495 | AP8: =AO8=Y8 -> FALSE | AR8: =IFERROR(VLOOKUP(AX7,'[2]Availability Des25'!$C$5:$G$18,5,0),0) -> 0 | AS8: =IFERROR(VLOOKUP(AX7,'[2]Availability Des25'!$C$5:$H$18,6,0),0) -> 0 | AT8: =IFERROR(VLOOKUP(AX7,'[2]Availability Des25'!$C$5:$I$18,7,0),0) -> 0
A9: =A8+1 -> 4 | B9: KANTOR PUSAT | C9: {=_xlfn.XLOOKUP(G9,DATABASE!$A$2:$A$809,DATABASE!$B$2:$B$809)} -> Bank Jatim u/ PT ACS, JL. Soekarno Hatta 269,Bandung (SMS Banking Primary) | D9: {=_xlfn.XLOOKUP(G9,DATABASE!$A$2:$A$809,DATABASE!$C$2:$C$809)} -> H2H | E9: TELKOM VPN IP | F9: PEMUTUSAN | G9: 4700020-0004645351 | H9: 202512 | I9: 512 Kbps | L9: 192.168.151.150 /30 | M9: 3/14/2015 | O9: 5.95 | Q9: =(O9*24*3600*30/8)/100000 -> 19.278 | R9: =(P9*24*3600*30/8)/100000 -> 0 | S9: 0 | T9: =(V9-S9)/V9*100% -> 1 | U9: 0.99 | V9: 720 | W9: =IF(T9<99%,((S9-V9)/720)*Y9,0) -> 0 | X9: 0.00 | Y9: 0 | AB9: 1391891 | AE9: =SUM(Y9:AD9) -> 1391891 | AF9: =IFERROR(AE9+W9,0) -> 1391891 | AI9: PEMUTUSAN 18 DES 2025 | AJ9: 4700020-0004645351 | AK9: 512 Kbps | AM9: =VLOOKUP(AJ9,'[1]Master Jaringan Des 2025(792)'!$D$2:$E$795,2,0) -> #REF! | AN9: =AM9=AK9 -> #REF! | AO9: 2319819 | AP9: =AO9=Y9 -> FALSE | AR9: =IFERROR(VLOOKUP(AX8,'[2]Availability Des25'!$C$5:$G$18,5,0),0) -> 0 | AS9: =IFERROR(VLOOKUP(AX8,'[2]Availability Des25'!$C$5:$H$18,6,0),0) -> 0 | AT9: =IFERROR(VLOOKUP(AX8,'[2]Availability Des25'!$C$5:$I$18,7,0),0) -> 0
A10: =A9+1 -> 5 | B10: KANTOR PUSAT | C10: {=_xlfn.XLOOKUP(G10,DATABASE!$A$2:$A$806,DATABASE!$B$2:$B$806)} -> Bank Jatim u/ Host To Host Finnet ; Jl Kapt.Subijanto Graha Telkom Sigma Lt. 3 BSD Lekong - Serpong | D10: {=_xlfn.XLOOKUP(G10,DATABASE!$A$2:$A$809,DATABASE!$C$2:$C$809)} -> H2H | E10: TELKOM VPN IP | F10: EKSISTING | G10: 4700020-92381 | H10: 202512 | I10: 512 Kbps | L10: 10.2.254.73 /30 | M10: 42278 | O10: 1.72108 | Q10: =(O10*24*3600*30/8)/100000 -> 5.5762992 | R10: =(P10*24*3600*30/8)/100000 -> 0 | S10: 0 | T10: =(V10-S10)/V10*100% -> 1 | U10: 0.99 | V10: 720 | W10: =IF(T10<99%,((S10-V10)/720)*Y10,0) -> 0 | X10: 0.00 | Y10: 2319819 | AE10: =SUM(Y10:AD10) -> 2319819 | AF10: =IFERROR(AE10+W10,0) -> 2319819 | AJ10: 4700020-92381 | AK10: 512 Kbps | AM10: =VLOOKUP(AJ10,'[1]Master Jaringan Des 2025(792)'!$D$2:$E$795,2,0) -> #REF! | AN10: =AM10=AK10 -> #REF! | AO10: 2319819 | AP10: =AO10=Y10 -> TRUE | AR10: =IFERROR(VLOOKUP(AX9,'[2]Availability Des25'!$C$5:$G$18,5,0),0) -> 0 | AS10: =IFERROR(VLOOKUP(AX9,'[2]Availability Des25'!$C$5:$H$18,6,0),0) -> 0 | AT10: =IFERROR(VLOOKUP(AX9,'[2]Availability Des25'!$C$5:$I$18,7,0),0) -> 0
A11: =A10+1 -> 6 | B11: KANTOR PUSAT | C11: {=_xlfn.XLOOKUP(G11,DATABASE!$A$2:$A$806,DATABASE!$B$2:$B$806)} -> Bank Jatim u/ Host To Host MPN G2 KEMENKEU; Graha Telkom Sigma Lt 3 BSD Tangerang | D11: {=_xlfn.XLOOKUP(G11,DATABASE!$A$2:$A$809,DATABASE!$C$2:$C$809)} -> H2H | E11: TELKOM VPN IP | F11: EKSISTING | G11: 4700020-0020988266 | H11: 202512 | I11: 512 Kbps | L11: 172.31.187.161 /30 | M11: 42099 | O11: 15.3 | Q11: =(O11*24*3600*30/8)/100000 -> 49.572 | R11: =(P11*24*3600*30/8)/100000 -> 0 | S11: 0 | T11: =(V11-S11)/V11*100% -> 1 | U11: 0.99 | V11: 720 | W11: =IF(T11<99%,((S11-V11)/720)*Y11,0) -> 0 | X11: 0.00 | Y11: 2319819 | AE11: =SUM(Y11:AD11) -> 2319819 | AF11: =IFERROR(AE11+W11,0) -> 2319819 | AJ11: 4700020-0020988266 | AK11: 512 Kbps | AM11: =VLOOKUP(AJ11,'[1]Master Jaringan Des 2025(792)'!$D$2:$E$795,2,0) -> #REF! | AN11: =AM11=AK11 -> #REF! | AO11: 2319819 | AP11: =AO11=Y11 -> TRUE | AR11: =IFERROR(VLOOKUP(AX10,'[2]Availability Des25'!$C$5:$G$18,5,0),0) -> 0 | AS11: =IFERROR(VLOOKUP(AX10,'[2]Availability Des25'!$C$5:$H$18,6,0),0) -> 0 | AT11: =IFERROR(VLOOKUP(AX10,'[2]Availability Des25'!$C$5:$I$18,7,0),0) -> 0
A12: =A11+1 -> 7 | B12: KANTOR PUSAT | C12: {=_xlfn.XLOOKUP(G12,DATABASE!$A$2:$A$806,DATABASE!$B$2:$B$806)} -> Bank Jatim u/ Bandwith Pelaporan Aplikasi BI-RTGS/SSSS/ETP, Bank Indonesia - RTGS; Telkom Sigma Lakarsantri IVC Surabaya | D12: {=_xlfn.XLOOKUP(G12,DATABASE!$A$2:$A$809,DATABASE!$C$2:$C$809)} -> Aplikasi BI-RTGS/SSSS/ETP BI | E12: TELKOM MANAGED NETWORK | F12: EKSISTING | G12: 1-IPP6AAY/1703056946 | H12: 202512 | I12: 2 Mbps | L12: 172.16.205.109/30 | M12: 1/13/2022 | O12: 86.18 | Q12: =(O12*24*3600*30/8)/100000 -> 279.2232 | R12: =(P12*24*3600*30/8)/100000 -> 0 | S12: 0 | T12: =(V12-S12)/V12*100% -> 1 | U12: 0.99 | V12: 720 | W12: =IF(T12<99%,((S12-V12)/720)*Y12,0) -> 0 | X12: 0.00 | Y12: 5782000 | AE12: =SUM(Y12:AD12) -> 5782000 | AF12: =IFERROR(AE12+W12,0) -> 5782000 | AI12: Kesepakatan REKON APR 2026 AM Safir dan Pak Rai SID ini BW TETAP di tulis 2Mbps diinvois HARGA PKS Baru , WALO PE 4Mbps | AJ12: 1-IPP6AAY/1703056946 | AK12: 2 Mbps | AM12: =VLOOKUP(AJ12,'[1]Master Jaringan Des 2025(792)'!$D$2:$E$795,2,0) -> #REF! | AN12: =AM12=AK12 -> #REF! | AO12: 5782000 | AP12: =AO12=Y12 -> TRUE | AR12: =IFERROR(VLOOKUP(AX11,'[2]Availability Des25'!$C$5:$G$18,5,0),0) -> 0 | AS12: =IFERROR(VLOOKUP(AX11,'[2]Availability Des25'!$C$5:$H$18,6,0),0) -> 0 | AT12: =IFERROR(VLOOKUP(AX11,'[2]Availability Des25'!$C$5:$I$18,7,0),0) -> 0
A13: =A12+1 -> 8 | B13: KANTOR PUSAT | C13: {=_xlfn.XLOOKUP(G13,DATABASE!$A$2:$A$806,DATABASE!$B$2:$B$806)} -> Bank Jatim u/ Host To Host Artajasa Sigma; Jl. Bukit Bali B3 Lakarsantri Surabaya Lt.3 | D13: {=_xlfn.XLOOKUP(G13,DATABASE!$A$2:$A$809,DATABASE!$C$2:$C$809)} -> SPP ONLINE | E13: TELKOM VPN IP | F13: EKSISTING | G13: 4700020-0029217410 | H13: 202512 | I13: 512 Kbps | L13: 10.240.0.2 /30 | M13: 42440 | O13: 0.07125 | Q13: =(O13*24*3600*30/8)/100000 -> 0.23085 | R13: =(P13*24*3600*30/8)/100000 -> 0 | S13: 0 | T13: =(V13-S13)/V13*100% -> 1 | U13: 0.99 | V13: 720 | W13: =IF(T13<99%,((S13-V13)/720)*Y13,0) -> 0 | X13: 0.00 | Y13: 2319819 | AE13: =SUM(Y13:AD13) -> 2319819 | AF13: =IFERROR(AE13+W13,0) -> 2319819 | AJ13: 4700020-0029217410 | AK13: 512 Kbps | AM13: =VLOOKUP(AJ13,'[1]Master Jaringan Des 2025(792)'!$D$2:$E$795,2,0) -> #REF! | AN13: =AM13=AK13 -> #REF! | AO13: 2319819 | AP13: =AO13=Y13 -> TRUE | AR13: =IFERROR(VLOOKUP(AX12,'[2]Availability Des25'!$C$5:$G$18,5,0),0) -> 0 | AS13: =IFERROR(VLOOKUP(AX12,'[2]Availability Des25'!$C$5:$H$18,6,0),0) -> 0 | AT13: =IFERROR(VLOOKUP(AX12,'[2]Availability Des25'!$C$5:$I$18,7,0),0) -> 0
A14: =A13+1 -> 9 | B14: KANTOR PUSAT | C14: {=_xlfn.XLOOKUP(G14,DATABASE!$A$2:$A$806,DATABASE!$B$2:$B$806)} -> Bank Jatim u/ Host To Host KTP-el Ditjen Dukcapil; DC Sigma Tangerang Lt.3 Wing timur, BSD Tangerang | D14: {=_xlfn.XLOOKUP(G14,DATABASE!$A$2:$A$809,DATABASE!$C$2:$C$809)} -> H2H | E14: TELKOM VPN IP | F14: EKSISTING | G14: 4700020-0029298844 | H14: 202512 | I14: 2 Mbps | L14: 10.240.0.6 /30 | M14: 4/13/2016 | O14: 12.9 | Q14: =(O14*24*3600*30/8)/100000 -> 41.796 | R14: =(P14*24*3600*30/8)/100000 -> 0 | S14: 0 | T14: =(V14-S14)/V14*100% -> 1 | U14: 0.99 | V14: 720 | W14: =IF(T14<99%,((S14-V14)/720)*Y14,0) -> 0 | X14: 0.00 | Y14: 3671171 | AE14: =SUM(Y14:AD14) -> 3671171 | AF14: =IFERROR(AE14+W14,0) -> 3671171 | AJ14: 4700020-0029298844 | AK14: 2 Mbps | AM14: =VLOOKUP(AJ14,'[1]Master Jaringan Des 2025(792)'!$D$2:$E$795,2,0) -> #REF! | AN14: =AM14=AK14 -> #REF! | AO14: 3671171 | AP14: =AO14=Y14 -> TRUE | AR14: =IFERROR(VLOOKUP(AX13,'[2]Availability Des25'!$C$5:$G$18,5,0),0) -> 0 | AS14: =IFERROR(VLOOKUP(AX13,'[2]Availability Des25'!$C$5:$H$18,6,0),0) -> 0 | AT14: =IFERROR(VLOOKUP(AX13,'[2]Availability Des25'!$C$5:$I$18,7,0),0) -> 0
A15: =A14+1 -> 10 | B15: KANTOR PUSAT | C15: {=_xlfn.XLOOKUP(G15,DATABASE!$A$2:$A$806,DATABASE!$B$2:$B$806)} -> Bank Jatim u/ Host To Host Call Center Infomedia; Jl. A. Yani 88, Lt.4, Surabaya | D15: {=_xlfn.XLOOKUP(G15,DATABASE!$A$2:$A$809,DATABASE!$C$2:$C$809)} -> CALL CENTER INFOMEDIA | E15: TELKOM VPN IP | F15: EKSISTING | G15: 4700020-0030913016 | H15: 202512 | I15: 10 Mbps | L15: 192.168.151.174 /30 | M15: 5/26/2017 | O15: 6.44 | Q15: =(O15*24*3600*30/8)/100000 -> 20.8656 | R15: =(P15*24*3600*30/8)/100000 -> 0 | S15: 0 | T15: =(V15-S15)/V15*100% -> 1 | U15: 0.99 | V15: 720 | W15: =IF(T15<99%,((S15-V15)/720)*Y15,0) -> 0 | X15: 0.00 | Y15: 9800000 | AE15: =SUM(Y15:AD15) -> 9800000 | AF15: =IFERROR(AE15+W15,0) -> 9800000 | AJ15: 4700020-0030913016 | AK15: 10 Mbps | AM15: =VLOOKUP(AJ15,'[1]Master Jaringan Des 2025(792)'!$D$2:$E$795,2,0) -> #REF! | AN15: =AM15=AK15 -> #REF! | AO15: 9800000 | AP15: =AO15=Y15 -> TRUE | AR15: =IFERROR(VLOOKUP(AX14,'[2]Availability Des25'!$C$5:$G$18,5,0),0) -> 0 | AS15: =IFERROR(VLOOKUP(AX14,'[2]Availability Des25'!$C$5:$H$18,6,0),0) -> 0 | AT15: =IFERROR(VLOOKUP(AX14,'[2]Availability Des25'!$C$5:$I$18,7,0),0) -> 0
A16: =A15+1 -> 11 | B16: KANTOR PUSAT | C16: {=_xlfn.XLOOKUP(G16,DATABASE!$A$2:$A$806,DATABASE!$B$2:$B$806)} -> Bank Jatim u/ Internet DRC Bank Jatim; JL.Citraland Surabaya ( Astinet ) | D16: {=_xlfn.XLOOKUP(G16,DATABASE!$A$2:$A$809,DATABASE!$C$2:$C$809)} -> INTERNET KANTOR PUSAT | E16: TELKOM ASTINET | F16: EKSISTING | G16: 4700020-0031230943 | H16: 202512 | I16: 12 Mbps | L16: 172.17.171.38 /30 (36.89.37.209 /28) | M16: 12/29/2017 | O16: 515.17 | Q16: =(O16*24*3600*30/8)/100000 -> 1669.1508 | R16: =(P16*24*3600*30/8)/100000 -> 0 | S16: 0 | T16: =(V16-S16)/V16*100% -> 1 | U16: 0.99 | V16: 720 | W16: =IF(T16<99%,((S16-V16)/720)*Y16,0) -> 0 | X16: 0.00 | Y16: 2940000 | AE16: =SUM(Y16:AD16) -> 2940000 | AF16: =IFERROR(AE16+W16,0) -> 2940000 | AJ16: 4700020-0031230943 | AK16: 12 Mbps | AM16: =VLOOKUP(AJ16,'[1]Master Jaringan Des 2025(792)'!$D$2:$E$795,2,0) -> #REF! | AN16: =AM16=AK16 -> #REF! | AO16: 2940000 | AP16: =AO16=Y16 -> TRUE | AR16: =IFERROR(VLOOKUP(AX15,'[2]Availability Des25'!$C$5:$G$18,5,0),0) -> 0 | AS16: =IFERROR(VLOOKUP(AX15,'[2]Availability Des25'!$C$5:$H$18,6,0),0) -> 0 | AT16: =IFERROR(VLOOKUP(AX15,'[2]Availability Des25'!$C$5:$I$18,7,0),0) -> 0
A17: =A16+1 -> 12 | B17: KANTOR PUSAT | C17: {=_xlfn.XLOOKUP(G17,DATABASE!$A$2:$A$806,DATABASE!$B$2:$B$806)} -> Bank Jatim Backhaul VPN IP DC; Graha Telkom Sigma Lt 3 BSD Tangerang | D17: {=_xlfn.XLOOKUP(G17,DATABASE!$A$2:$A$809,DATABASE!$C$2:$C$809)} -> DC | E17: TELKOM VPN IP | F17: EKSISTING | G17: 4700020-82572 | H17: 202512 | I17: 100 Mbps | L17: 172.17.20.2 /30 | M17: 42186 | N17: 46022 | O17: 30904.32 | Q17: =(O17*24*3600*30/8)/100000 -> 100130 | R17: =(P17*24*3600*30/8)/100000 -> 0 | S17: 0 | T17: =(V17-S17)/V17*100% -> 1 | U17: 0.99 | V17: 720 | W17: =IF(T17<99%,((S17-V17)/720)*Y17,0) -> 0 | X17: 0.00 | Y17: 20776000 | AE17: =SUM(Y17:AD17) -> 20776000 | AF17: =IFERROR(AE17+W17,0) -> 20776000 | AI17: Upgrade Bandwidth Temporer kegiatan akhir tahun 2025, Tidak merubah abonemen | AJ17: 4700020-82572 | AK17: 100 Mbps | AM17: =VLOOKUP(AJ17,'[1]Master Jaringan Des 2025(792)'!$D$2:$E$795,2,0) -> #REF! | AN17: =AM17=AK17 -> #REF! | AO17: 20776000 | AP17: =AO17=Y17 -> TRUE | AR17: =IFERROR(VLOOKUP(AX16,'[2]Availability Des25'!$C$5:$G$18,5,0),0) -> 0 | AS17: =IFERROR(VLOOKUP(AX16,'[2]Availability Des25'!$C$5:$H$18,6,0),0) -> 0 | AT17: =IFERROR(VLOOKUP(AX16,'[2]Availability Des25'!$C$5:$I$18,7,0),0) -> 0
A18: =A17+1 -> 13 | B18: KANTOR PUSAT | C18: {=_xlfn.XLOOKUP(G18,DATABASE!$A$2:$A$806,DATABASE!$B$2:$B$806)} -> Bank Jatim Backhaul VPN IP DRC; Bukit Bali B3-2 Lakarsantri Surabaya | D18: {=_xlfn.XLOOKUP(G18,DATABASE!$A$2:$A$809,DATABASE!$C$2:$C$809)} -> DRC | E18: TELKOM VPN IP | F18: EKSISTING | G18: 4700020-68390 | H18: 202512 | I18: 100 Mbps | L18: 172.17.52.2 /30 | M18: 6/24/2015 | O18: 26818.56 | Q18: =(O18*24*3600*30/8)/100000 -> 86892.134 | R18: =(P18*24*3600*30/8)/100000 -> 0 | S18: 0 | T18: =(V18-S18)/V18*100% -> 1 | U18: 0.99 | V18: 720 | W18: =IF(T18<99%,((S18-V18)/720)*Y18,0) -> 0 | X18: 0.00 | Y18: 20776000 | AE18: =SUM(Y18:AD18) -> 20776000 | AF18: =IFERROR(AE18+W18,0) -> 20776000 | AJ18: 4700020-68390 | AK18: 100 Mbps | AM18: =VLOOKUP(AJ18,'[1]Master Jaringan Des 2025(792)'!$D$2:$E$795,2,0) -> #REF! | AN18: =AM18=AK18 -> #REF! | AO18: 20776000 | AP18: =AO18=Y18 -> TRUE | AR18: =IFERROR(VLOOKUP(AX17,'[2]Availability Des25'!$C$5:$G$18,5,0),0) -> 0 | AS18: =IFERROR(VLOOKUP(AX17,'[2]Availability Des25'!$C$5:$H$18,6,0),0) -> 0 | AT18: =IFERROR(VLOOKUP(AX17,'[2]Availability Des25'!$C$5:$I$18,7,0),0) -> 0
A19: =A18+1 -> 14 | B19: KANTOR PUSAT | C19: {=_xlfn.XLOOKUP(G19,DATABASE!$A$2:$A$806,DATABASE!$B$2:$B$806)} -> Bank Jatim u/ Host To Host Metro DJP-DC; Jl. Gatot Subroto Kav. 40-42 JKT ke DC Sigma Citraland SBY (E-Filling) | D19: {=_xlfn.XLOOKUP(G19,DATABASE!$A$2:$A$808,DATABASE!$C$2:$C$808)} -> H2H METRO | E19: TELKOM METRO | F19: EKSISTING | G19: 4700020-0029669221 | H19: 202512 | I19: 1 Mbps | L19: - | M19: 1/26/2016 | O19: 3.91 | Q19: =(O19*24*3600*30/8)/100000 -> 12.6684 | R19: =(P19*24*3600*30/8)/100000 -> 0 | S19: 0 | T19: =(V19-S19)/V19*100% -> 1 | U19: 0.99 | V19: 720 | W19: =IF(T19<99%,((S19-V19)/720)*Y19,0) -> 0 | X19: 0.00 | Y19: 2737114 | AE19: =SUM(Y19:AD19) -> 2737114 | AF19: =IFERROR(AE19+W19,0) -> 2737114 | AJ19: 4700020-0029669221 | AK19: 1 Mbps | AM19: =VLOOKUP(AJ19,'[1]Master Jaringan Des 2025(792)'!$D$2:$E$795,2,0) -> #REF! | AN19: =AM19=AK19 -> #REF! | AO19: 2737114 | AP19: =AO19=Y19 -> TRUE | AQ19: H2H METRO | AR19: =IFERROR(VLOOKUP(AX18,'[2]Availability Des25'!$C$5:$G$18,5,0),0) -> 0 | AS19: =IFERROR(VLOOKUP(AX18,'[2]Availability Des25'!$C$5:$H$18,6,0),0) -> 0 | AT19: =IFERROR(VLOOKUP(AX18,'[2]Availability Des25'!$C$5:$I$18,7,0),0) -> 0
A20: =A19+1 -> 15 | B20: KANTOR PUSAT | C20: {=_xlfn.XLOOKUP(G20,DATABASE!$A$2:$A$806,DATABASE!$B$2:$B$806)} -> Bank Jatim u/ Host To Host Metro DC -DJP; DC Sigma Citraland SBY ke Jl. Gatot Subroto Kav. 40-42 JKT (E-Filling) | D20: {=_xlfn.XLOOKUP(G20,DATABASE!$A$2:$A$808,DATABASE!$C$2:$C$808)} -> H2H METRO | E20: TELKOM METRO | F20: EKSISTING | G20: 4700020-0030871897 | H20: 202512 | I20: 1 Mbps | L20: - | M20: 4/18/2017 | O20: 0.47008 | Q20: =(O20*24*3600*30/8)/100000 -> 1.5230592 | R20: =(P20*24*3600*30/8)/100000 -> 0 | S20: 0 | T20: =(V20-S20)/V20*100% -> 1 | U20: 0.99 | V20: 720 | W20: =IF(T20<99%,((S20-V20)/720)*Y20,0) -> 0 | X20: 0.00 | Y20: 2737114 | AE20: =SUM(Y20:AD20) -> 2737114 | AF20: =IFERROR(AE20+W20,0) -> 2737114 | AJ20: 4700020-0030871897 | AK20: 1 Mbps | AM20: =VLOOKUP(AJ20,'[1]Master Jaringan Des 2025(792)'!$D$2:$E$795,2,0) -> #REF! | AN20: =AM20=AK20 -> #REF! | AO20: 2737114 | AP20: =AO20=Y20 -> TRUE | AQ20: H2H METRO | AR20: =IFERROR(VLOOKUP(AX19,'[2]Availability Des25'!$C$5:$G$18,5,0),0) -> 0 | AS20: =IFERROR(VLOOKUP(AX19,'[2]Availability Des25'!$C$5:$H$18,6,0),0) -> 0 | AT20: =IFERROR(VLOOKUP(AX19,'[2]Availability Des25'!$C$5:$I$18,7,0),0) -> 0
A21: =A20+1 -> 16 | B21: KANTOR PUSAT | C21: {=_xlfn.XLOOKUP(G21,DATABASE!$A$2:$A$806,DATABASE!$B$2:$B$806)} -> Bank Jatim u/ Host To Host Metro Asabri -DC; Jl.Mayjen Sutoyo 11 JakTim | D21: {=_xlfn.XLOOKUP(G21,DATABASE!$A$2:$A$808,DATABASE!$C$2:$C$808)} -> H2H METRO | E21: TELKOM METRO | F21: EKSISTING | G21: 4700020-0031134693 | H21: 202512 | I21: 1 Mbps | L21: - | M21: 10/26/2017 | O21: 114.11 | Q21: =(O21*24*3600*30/8)/100000 -> 369.7164 | R21: =(P21*24*3600*30/8)/100000 -> 0 | S21: 0 | T21: =(V21-S21)/V21*100% -> 1 | U21: 0.99 | V21: 720 | W21: =IF(T21<99%,((S21-V21)/720)*Y21,0) -> 0 | X21: 0.00 | Y21: 2737114 | AE21: =SUM(Y21:AD21) -> 2737114 | AF21: =IFERROR(AE21+W21,0) -> 2737114 | AJ21: 4700020-0031134693 | AK21: 1 Mbps | AM21: =VLOOKUP(AJ21,'[1]Master Jaringan Des 2025(792)'!$D$2:$E$795,2,0) -> #REF! | AN21: =AM21=AK21 -> #REF! | AO21: 2737114 | AP21: =AO21=Y21 -> TRUE | AQ21: H2H METRO | AR21: =IFERROR(VLOOKUP(AX20,'[2]Availability Des25'!$C$5:$G$18,5,0),0) -> 0 | AS21: =IFERROR(VLOOKUP(AX20,'[2]Availability Des25'!$C$5:$H$18,6,0),0) -> 0 | AT21: =IFERROR(VLOOKUP(AX20,'[2]Availability Des25'!$C$5:$I$18,7,0),0) -> 0
A22: =A21+1 -> 17 | B22: KANTOR PUSAT | C22: {=_xlfn.XLOOKUP(G22,DATABASE!$A$2:$A$806,DATABASE!$B$2:$B$806)} -> Bank Jatim u/ Host To Host Metro DC- Asabri; Sigma Citraland Jl.Bukit Bali B3 2 Lakarsantri Surabaya | D22: {=_xlfn.XLOOKUP(G22,DATABASE!$A$2:$A$808,DATABASE!$C$2:$C$808)} -> H2H METRO | E22: TELKOM METRO | F22: EKSISTING | G22: 4700020-0031135108 | H22: 202512 | I22: 1 Mbps | L22: - | M22: 10/31/2017 | O22: 0.48568 | Q22: =(O22*24*3600*30/8)/100000 -> 1.5736032 | R22: =(P22*24*3600*30/8)/100000 -> 0 | S22: 0 | T22: =(V22-S22)/V22*100% -> 1 | U22: 0.99 | V22: 720 | W22: =IF(T22<99%,((S22-V22)/720)*Y22,0) -> 0 | X22: 0.00 | Y22: 2737114 | AE22: =SUM(Y22:AD22) -> 2737114 | AF22: =IFERROR(AE22+W22,0) -> 2737114 | AJ22: 4700020-0031135108 | AK22: 1 Mbps | AM22: =VLOOKUP(AJ22,'[1]Master Jaringan Des 2025(792)'!$D$2:$E$795,2,0) -> #REF! | AN22: =AM22=AK22 -> #REF! | AO22: 2737114 | AP22: =AO22=Y22 -> TRUE | AQ22: H2H METRO | AR22: =IFERROR(VLOOKUP(AX21,'[2]Availability Des25'!$C$5:$G$18,5,0),0) -> 0 | AS22: =IFERROR(VLOOKUP(AX21,'[2]Availability Des25'!$C$5:$H$18,6,0),0) -> 0 | AT22: =IFERROR(VLOOKUP(AX21,'[2]Availability Des25'!$C$5:$I$18,7,0),0) -> 0
A23: =A22+1 -> 18 | B23: KANTOR PUSAT | C23: {=_xlfn.XLOOKUP(G23,DATABASE!$A$2:$A$806,DATABASE!$B$2:$B$806)} -> Bank Jatim u/ Host To Host Metro P2P DC-MKM; Data Center Jl. Gedung German Center Lt. 3, BSD Tangerang ke DCI Bekasi (H2H MKM DCI Tangerang) | D23: {=_xlfn.XLOOKUP(G23,DATABASE!$A$2:$A$808,DATABASE!$C$2:$C$808)} -> H2H METRO | E23: TELKOM METRO | F23: EKSISTING | G23: 790038103 | H23: 202512 | I23: 1 Mbps | L23: - | M23: 43497 | O23: 68.86 | Q23: =(O23*24*3600*30/8)/100000 -> 223.1064 | R23: =(P23*24*3600*30/8)/100000 -> 0 | S23: 0 | T23: =(V23-S23)/V23*100% -> 1 | U23: 0.99 | V23: 720 | W23: =IF(T23<99%,((S23-V23)/720)*Y23,0) -> 0 | X23: 0.00 | Y23: 2737114 | AE23: =SUM(Y23:AD23) -> 2737114 | AF23: =IFERROR(AE23+W23,0) -> 2737114 | AJ23: 790038103 | AK23: 1 Mbps | AM23: 1 Mbps | AN23: =AM23=AK23 -> TRUE | AO23: 2737114 | AP23: =AO23=Y23 -> TRUE | AQ23: H2H METRO | AR23: =IFERROR(VLOOKUP(AX22,'[2]Availability Des25'!$C$5:$G$18,5,0),0) -> 0 | AS23: =IFERROR(VLOOKUP(AX22,'[2]Availability Des25'!$C$5:$H$18,6,0),0) -> 0 | AT23: =IFERROR(VLOOKUP(AX22,'[2]Availability Des25'!$C$5:$I$18,7,0),0) -> 0
